Traceback (most recent call last):
  File "/Users/dialidsantiago/Git/Understanding-Quantitative-Finance/.venv/lib/python3.11/site-packages/jupyter_cache/executors/utils.py", line 58, in single_nb_execution
    executenb(
  File "/Users/dialidsantiago/Git/Understanding-Quantitative-Finance/.venv/lib/python3.11/site-packages/nbclient/client.py", line 1305, in execute
    return NotebookClient(nb=nb, resources=resources, km=km, **kwargs).execute()
           ^^^^^^^^^^^^^^^^^^^^^^^^^^^^^^^^^^^^^^^^^^^^^^^^^^^^^^^^^^^^^^^^^^^^^
  File "/Users/dialidsantiago/Git/Understanding-Quantitative-Finance/.venv/lib/python3.11/site-packages/jupyter_core/utils/__init__.py", line 165, in wrapped
    return loop.run_until_complete(inner)
           ^^^^^^^^^^^^^^^^^^^^^^^^^^^^^^
  File "/Library/Frameworks/Python.framework/Versions/3.11/lib/python3.11/asyncio/base_events.py", line 653, in run_until_complete
    return future.result()
           ^^^^^^^^^^^^^^^
  File "/Users/dialidsantiago/Git/Understanding-Quantitative-Finance/.venv/lib/python3.11/site-packages/nbclient/client.py", line 705, in async_execute
    await self.async_execute_cell(
  File "/Users/dialidsantiago/Git/Understanding-Quantitative-Finance/.venv/lib/python3.11/site-packages/nbclient/client.py", line 1058, in async_execute_cell
    await self._check_raise_for_error(cell, cell_index, exec_reply)
  File "/Users/dialidsantiago/Git/Understanding-Quantitative-Finance/.venv/lib/python3.11/site-packages/nbclient/client.py", line 914, in _check_raise_for_error
    raise CellExecutionError.from_cell_and_msg(cell, exec_reply_content)
nbclient.exceptions.CellExecutionError: An error occurred while executing the following cell:
------------------
from scipy.stats import ncx2
import numpy as np 

x0 = 2.0 
theta = 1.0
mu = 3.0
sigma = 0.5
t =1.0 

delta = 4.0 * theta * mu / sigma**2
alpha = (4.0 * theta * x0) / (sigma**2 * (np.exp(theta*t)-1.0))
scale = (sigma**2 / 4.0 * theta) * (1.0 - np.exp(-1.0*theta*t))
X_1 = ncx2(df=delta,nc=alpha,scale=scale)


# Now we can calculate the mean and the variance of X_1
print(X_1.mean()) 
print(X_1.var())
------------------


[0;31m---------------------------------------------------------------------------[0m
[0;31mModuleNotFoundError[0m                       Traceback (most recent call last)
Cell [0;32mIn[2], line 1[0m
[0;32m----> 1[0m [38;5;28;01mfrom[39;00m[38;5;250m [39m[38;5;21;01mscipy[39;00m[38;5;21;01m.[39;00m[38;5;21;01mstats[39;00m[38;5;250m [39m[38;5;28;01mimport[39;00m ncx2
[1;32m      2[0m [38;5;28;01mimport[39;00m[38;5;250m [39m[38;5;21;01mnumpy[39;00m[38;5;250m [39m[38;5;28;01mas[39;00m[38;5;250m [39m[38;5;21;01mnp[39;00m 
[1;32m      4[0m x0 [38;5;241m=[39m [38;5;241m2.0[39m 

[0;31mModuleNotFoundError[0m: No module named 'scipy'

