Traceback (most recent call last):
  File "/Users/dialidsantiago/Git/Understanding-Quantitative-Finance/.venv/lib/python3.9/site-packages/jupyter_cache/executors/utils.py", line 51, in single_nb_execution
    executenb(
  File "/Users/dialidsantiago/Git/Understanding-Quantitative-Finance/.venv/lib/python3.9/site-packages/nbclient/client.py", line 1204, in execute
    return NotebookClient(nb=nb, resources=resources, km=km, **kwargs).execute()
  File "/Users/dialidsantiago/Git/Understanding-Quantitative-Finance/.venv/lib/python3.9/site-packages/nbclient/util.py", line 84, in wrapped
    return just_run(coro(*args, **kwargs))
  File "/Users/dialidsantiago/Git/Understanding-Quantitative-Finance/.venv/lib/python3.9/site-packages/nbclient/util.py", line 62, in just_run
    return loop.run_until_complete(coro)
  File "/Library/Frameworks/Python.framework/Versions/3.9/lib/python3.9/asyncio/base_events.py", line 642, in run_until_complete
    return future.result()
  File "/Users/dialidsantiago/Git/Understanding-Quantitative-Finance/.venv/lib/python3.9/site-packages/nbclient/client.py", line 663, in async_execute
    await self.async_execute_cell(
  File "/Users/dialidsantiago/Git/Understanding-Quantitative-Finance/.venv/lib/python3.9/site-packages/nbclient/client.py", line 965, in async_execute_cell
    await self._check_raise_for_error(cell, cell_index, exec_reply)
  File "/Users/dialidsantiago/Git/Understanding-Quantitative-Finance/.venv/lib/python3.9/site-packages/nbclient/client.py", line 862, in _check_raise_for_error
    raise CellExecutionError.from_cell_and_msg(cell, exec_reply_content)
nbclient.exceptions.CellExecutionError: An error occurred while executing the following cell:
------------------
draw_gbm_mean_variance(s0=1.0, mu=0.1, sigma=0.2, T=100)
------------------

[0;31m---------------------------------------------------------------------------[0m
[0;31mNameError[0m                                 Traceback (most recent call last)
Cell [0;32mIn[15], line 1[0m
[0;32m----> 1[0m [43mdraw_gbm_mean_variance[49m(s0[38;5;241m=[39m[38;5;241m1.0[39m, mu[38;5;241m=[39m[38;5;241m0.1[39m, sigma[38;5;241m=[39m[38;5;241m0.2[39m, T[38;5;241m=[39m[38;5;241m100[39m)

[0;31mNameError[0m: name 'draw_gbm_mean_variance' is not defined
NameError: name 'draw_gbm_mean_variance' is not defined

